<?xml version="1.0" encoding="utf-8"?>
<!-- This URDF was automatically created by SolidWorks to URDF Exporter! Originally created by Stephen Brawner (brawner@gmail.com) 
     Commit Version: 1.5.1-0-g916b5db  Build Version: 1.5.7152.31018
     For more information, please see http://wiki.ros.org/sw_urdf_exporter -->
<robot
  name="FullAssemV2_URDF_6">
  <link
    name="Base_Link">
    <inertial>
      <origin
        xyz="-0.00015378 0.0059831 0.0018543"
        rpy="0 0 0" />
      <mass
        value="0.2498" />
      <inertia
        ixx="0.00027052"
        ixy="-2.9032E-06"
        ixz="9.9718E-07"
        iyy="0.00056127"
        iyz="-1.828E-06"
        izz="0.00029671" />
    </inertial>
    <visual>
      <origin
        xyz="0 0 0"
        rpy="0 0 0" />
      <geometry>
        <mesh
          filename="package://FullAssemV2_URDF_6/meshes/Base_Link.STL" />
      </geometry>
      <material
        name="">
        <color
          rgba="0.75294 0.75294 0.75294 1" />
      </material>
    </visual>
    <collision>
      <origin
        xyz="0 0 0"
        rpy="0 0 0" />
      <geometry>
        <mesh
          filename="package://FullAssemV2_URDF_6/meshes/Base_Link.STL" />
      </geometry>
    </collision>
  </link>
  <link
    name="Thigh1_Link">
    <inertial>
      <origin
        xyz="-0.05457 0.014655 0.0029163"
        rpy="0 0 0" />
      <mass
        value="0.053996" />
      <inertia
        ixx="1.2958E-05"
        ixy="6.6702E-06"
        ixz="-2.6124E-08"
        iyy="2.2919E-05"
        iyz="-2.8182E-08"
        izz="2.4984E-05" />
    </inertial>
    <visual>
      <origin
        xyz="0 0 0"
        rpy="0 0 0" />
      <geometry>
        <mesh
          filename="package://FullAssemV2_URDF_6/meshes/Thigh1_Link.STL" />
      </geometry>
      <material
        name="">
        <color
          rgba="0.75294 0.75294 0.75294 1" />
      </material>
    </visual>
    <collision>
      <origin
        xyz="0 0 0"
        rpy="0 0 0" />
      <geometry>
        <mesh
          filename="package://FullAssemV2_URDF_6/meshes/Thigh1_Link.STL" />
      </geometry>
    </collision>
  </link>
  <joint
    name="Thigh1_Joint"
    type="continuous">
    <origin
      xyz="-0.039065 -0.053882 0"
      rpy="1.5708 0 0.098815" />
    <parent
      link="Base_Link" />
    <child
      link="Thigh1_Link" />
    <axis
      xyz="0 1 0" />
  </joint>
  <link
    name="Shin1_Link">
    <inertial>
      <origin
        xyz="0.089293 0.00052424 0.12407"
        rpy="0 0 0" />
      <mass
        value="0.057893" />
      <inertia
        ixx="5.1911E-06"
        ixy="-1.6884E-07"
        ixz="-2.1135E-06"
        iyy="9.8478E-05"
        iyz="-1.0817E-08"
        izz="9.4822E-05" />
    </inertial>
    <visual>
      <origin
        xyz="0 0 0"
        rpy="0 0 0" />
      <geometry>
        <mesh
          filename="package://FullAssemV2_URDF_6/meshes/Shin1_Link.STL" />
      </geometry>
      <material
        name="">
        <color
          rgba="0.75294 0.75294 0.75294 1" />
      </material>
    </visual>
    <collision>
      <origin
        xyz="0 0 0"
        rpy="0 0 0" />
      <geometry>
        <mesh
          filename="package://FullAssemV2_URDF_6/meshes/Shin1_Link.STL" />
      </geometry>
    </collision>
  </link>
  <joint
    name="Shin1_Joint"
    type="continuous">
    <origin
      xyz="0 0.078226 0"
      rpy="1.5708 0 -1.6593" />
    <parent
      link="Thigh1_Link" />
    <child
      link="Shin1_Link" />
    <axis
      xyz="0.99609 0 -0.088356" />
  </joint>
  <link
    name="Foot1_Link">
    <inertial>
      <origin
        xyz="-0.02178 0.14158 0.00015875"
        rpy="0 0 0" />
      <mass
        value="0.0091406" />
      <inertia
        ixx="1.4339E-06"
        ixy="6.6635E-08"
        ixz="1.9162E-14"
        iyy="7.4197E-07"
        iyz="-1.2833E-13"
        izz="1.335E-06" />
    </inertial>
    <visual>
      <origin
        xyz="0 0 0"
        rpy="0 0 0" />
      <geometry>
        <mesh
          filename="package://FullAssemV2_URDF_6/meshes/Foot1_Link.STL" />
      </geometry>
      <material
        name="">
        <color
          rgba="0.79216 0.81961 0.93333 1" />
      </material>
    </visual>
    <collision>
      <origin
        xyz="0 0 0"
        rpy="0 0 0" />
      <geometry>
        <mesh
          filename="package://FullAssemV2_URDF_6/meshes/Foot1_Link.STL" />
      </geometry>
    </collision>
  </link>
  <joint
    name="Foot1_Joint"
    type="continuous">
    <origin
      xyz="0.15134 0 -0.013424"
      rpy="1.5708 -0.088471 3.1416" />
    <parent
      link="Shin1_Link" />
    <child
      link="Foot1_Link" />
    <axis
      xyz="1 0 0" />
  </joint>
  <link
    name="Thigh2_Link">
    <inertial>
      <origin
        xyz="-0.042838 0.025441 0.0029163"
        rpy="0 0 0" />
      <mass
        value="0.053996" />
      <inertia
        ixx="2.4039E-05"
        ixy="5.7377E-06"
        ixz="-2.6382E-08"
        iyy="1.1839E-05"
        iyz="-2.842E-08"
        izz="2.4984E-05" />
    </inertial>
    <visual>
      <origin
        xyz="0 0 0"
        rpy="0 0 0" />
      <geometry>
        <mesh
          filename="package://FullAssemV2_URDF_6/meshes/Thigh2_Link.STL" />
      </geometry>
      <material
        name="">
        <color
          rgba="0.75294 0.75294 0.75294 1" />
      </material>
    </visual>
    <collision>
      <origin
        xyz="0 0 0"
        rpy="0 0 0" />
      <geometry>
        <mesh
          filename="package://FullAssemV2_URDF_6/meshes/Thigh2_Link.STL" />
      </geometry>
    </collision>
  </link>
  <joint
    name="Thigh2_Joint"
    type="continuous">
    <origin
      xyz="0.039065 -0.053882 0"
      rpy="1.5708 0 2.2782" />
    <parent
      link="Base_Link" />
    <child
      link="Thigh2_Link" />
    <axis
      xyz="0 1 0" />
  </joint>
  <link
    name="Shin2_Link">
    <inertial>
      <origin
        xyz="-0.029659 0.00052423 0.13554"
        rpy="0 0 0" />
      <mass
        value="0.057893" />
      <inertia
        ixx="5.1898E-06"
        ixy="-1.6896E-07"
        ixz="-2.1127E-06"
        iyy="9.8478E-05"
        iyz="-1.0889E-08"
        izz="9.4823E-05" />
    </inertial>
    <visual>
      <origin
        xyz="0 0 0"
        rpy="0 0 0" />
      <geometry>
        <mesh
          filename="package://FullAssemV2_URDF_6/meshes/Shin2_Link.STL" />
      </geometry>
      <material
        name="">
        <color
          rgba="0.75294 0.75294 0.75294 1" />
      </material>
    </visual>
    <collision>
      <origin
        xyz="0 0 0"
        rpy="0 0 0" />
      <geometry>
        <mesh
          filename="package://FullAssemV2_URDF_6/meshes/Shin2_Link.STL" />
      </geometry>
    </collision>
  </link>
  <joint
    name="Shin2_Joint"
    type="continuous">
    <origin
      xyz="0 -0.040937 0"
      rpy="1.5708 0 -2.095" />
    <parent
      link="Thigh2_Link" />
    <child
      link="Shin2_Link" />
    <axis
      xyz="0.86575 0 -0.50048" />
  </joint>
  <link
    name="Foot2_Link">
    <inertial>
      <origin
        xyz="0.0086849 0.14743 0.00015875"
        rpy="0 0 0" />
      <mass
        value="0.0091406" />
      <inertia
        ixx="1.4339E-06"
        ixy="6.6635E-08"
        ixz="9.0873E-14"
        iyy="7.4197E-07"
        iyz="-1.1846E-13"
        izz="1.335E-06" />
    </inertial>
    <visual>
      <origin
        xyz="0 0 0"
        rpy="0 0 0" />
      <geometry>
        <mesh
          filename="package://FullAssemV2_URDF_6/meshes/Foot2_Link.STL" />
      </geometry>
      <material
        name="">
        <color
          rgba="0.79216 0.81961 0.93333 1" />
      </material>
    </visual>
    <collision>
      <origin
        xyz="0 0 0"
        rpy="0 0 0" />
      <geometry>
        <mesh
          filename="package://FullAssemV2_URDF_6/meshes/Foot2_Link.STL" />
      </geometry>
    </collision>
  </link>
  <joint
    name="Foot2_Joint"
    type="continuous">
    <origin
      xyz="0 0 0"
      rpy="1.5708 -0.52416 3.1416" />
    <parent
      link="Shin2_Link" />
    <child
      link="Foot2_Link" />
    <axis
      xyz="1 0 0" />
  </joint>
  <link
    name="Thigh3_Link">
    <inertial>
      <origin
        xyz="-0.050482 0.020373 0.0029163"
        rpy="0 0 0" />
      <mass
        value="0.053996" />
      <inertia
        ixx="1.7864E-05"
        ixy="8.3469E-06"
        ixz="-2.6214E-08"
        iyy="1.8014E-05"
        iyz="-2.8308E-08"
        izz="2.4984E-05" />
    </inertial>
    <visual>
      <origin
        xyz="0 0 0"
        rpy="0 0 0" />
      <geometry>
        <mesh
          filename="package://FullAssemV2_URDF_6/meshes/Thigh3_Link.STL" />
      </geometry>
      <material
        name="">
        <color
          rgba="0.75294 0.75294 0.75294 1" />
      </material>
    </visual>
    <collision>
      <origin
        xyz="0 0 0"
        rpy="0 0 0" />
      <geometry>
        <mesh
          filename="package://FullAssemV2_URDF_6/meshes/Thigh3_Link.STL" />
      </geometry>
    </collision>
  </link>
  <joint
    name="Thigh3_Joint"
    type="continuous">
    <origin
      xyz="0.039433 0.05348 0"
      rpy="1.5708 0 -2.7838" />
    <parent
      link="Base_Link" />
    <child
      link="Thigh3_Link" />
    <axis
      xyz="0 1 0" />
  </joint>
  <link
    name="Shin3_Link">
    <inertial>
      <origin
        xyz="-0.017595 0.00052425 0.16111"
        rpy="0 0 0" />
      <mass
        value="0.057893" />
      <inertia
        ixx="5.1914E-06"
        ixy="-1.6879E-07"
        ixz="-2.1139E-06"
        iyy="9.8478E-05"
        iyz="-1.08E-08"
        izz="9.4822E-05" />
    </inertial>
    <visual>
      <origin
        xyz="0 0 0"
        rpy="0 0 0" />
      <geometry>
        <mesh
          filename="package://FullAssemV2_URDF_6/meshes/Shin3_Link.STL" />
      </geometry>
      <material
        name="">
        <color
          rgba="0.75294 0.75294 0.75294 1" />
      </material>
    </visual>
    <collision>
      <origin
        xyz="0 0 0"
        rpy="0 0 0" />
      <geometry>
        <mesh
          filename="package://FullAssemV2_URDF_6/meshes/Shin3_Link.STL" />
      </geometry>
    </collision>
  </link>
  <joint
    name="Shin3_Joint"
    type="continuous">
    <origin
      xyz="0 -0.061738 0"
      rpy="1.5708 0 -2.0801" />
    <parent
      link="Thigh3_Link" />
    <child
      link="Shin3_Link" />
    <axis
      xyz="0.87309 0 -0.48756" />
  </joint>
  <link
    name="Foot3_Link">
    <inertial>
      <origin
        xyz="0.0084624 0.17592 0.00015874"
        rpy="0 0 0" />
      <mass
        value="0.0091406" />
      <inertia
        ixx="1.4339E-06"
        ixy="6.6635E-08"
        ixz="4.0749E-13"
        iyy="7.4197E-07"
        iyz="-1.3487E-13"
        izz="1.335E-06" />
    </inertial>
    <visual>
      <origin
        xyz="0 0 0"
        rpy="0 0 0" />
      <geometry>
        <mesh
          filename="package://FullAssemV2_URDF_6/meshes/Foot3_Link.STL" />
      </geometry>
      <material
        name="">
        <color
          rgba="0.79216 0.81961 0.93333 1" />
      </material>
    </visual>
    <collision>
      <origin
        xyz="0 0 0"
        rpy="0 0 0" />
      <geometry>
        <mesh
          filename="package://FullAssemV2_URDF_6/meshes/Foot3_Link.STL" />
      </geometry>
    </collision>
  </link>
  <joint
    name="Foot3_Joint"
    type="continuous">
    <origin
      xyz="0 0 0"
      rpy="1.5708 -0.5093 3.1416" />
    <parent
      link="Shin3_Link" />
    <child
      link="Foot3_Link" />
    <axis
      xyz="1 0 0" />
  </joint>
  <link
    name="Thigh4_Link">
    <inertial>
      <origin
        xyz="-0.046262 0.023725 0.0029163"
        rpy="0 0 0" />
      <mass
        value="0.053996" />
      <inertia
        ixx="2.1756E-05"
        ixy="7.443E-06"
        ixz="-2.6307E-08"
        iyy="1.4122E-05"
        iyz="-2.8382E-08"
        izz="2.4984E-05" />
    </inertial>
    <visual>
      <origin
        xyz="0 0 0"
        rpy="0 0 0" />
      <geometry>
        <mesh
          filename="package://FullAssemV2_URDF_6/meshes/Thigh4_Link.STL" />
      </geometry>
      <material
        name="">
        <color
          rgba="0.75294 0.75294 0.75294 1" />
      </material>
    </visual>
    <collision>
      <origin
        xyz="0 0 0"
        rpy="0 0 0" />
      <geometry>
        <mesh
          filename="package://FullAssemV2_URDF_6/meshes/Thigh4_Link.STL" />
      </geometry>
    </collision>
  </link>
  <joint
    name="Thigh4_Joint"
    type="continuous">
    <origin
      xyz="-0.039433 0.05348 0"
      rpy="1.5708 0 -0.47257" />
    <parent
      link="Base_Link" />
    <child
      link="Thigh4_Link" />
    <axis
      xyz="0 1 0" />
  </joint>
  <link
    name="Shin4_Link">
    <inertial>
      <origin
        xyz="-0.069847 0.00052425 0.12515"
        rpy="0 0 0" />
      <mass
        value="0.057893" />
      <inertia
        ixx="5.1892E-06"
        ixy="-1.69E-07"
        ixz="-2.1127E-06"
        iyy="9.8478E-05"
        iyz="-1.0926E-08"
        izz="9.4824E-05" />
    </inertial>
    <visual>
      <origin
        xyz="0 0 0"
        rpy="0 0 0" />
      <geometry>
        <mesh
          filename="package://FullAssemV2_URDF_6/meshes/Shin4_Link.STL" />
      </geometry>
      <material
        name="">
        <color
          rgba="0.75294 0.75294 0.75294 1" />
      </material>
    </visual>
    <collision>
      <origin
        xyz="0 0 0"
        rpy="0 0 0" />
      <geometry>
        <mesh
          filename="package://FullAssemV2_URDF_6/meshes/Shin4_Link.STL" />
      </geometry>
    </collision>
  </link>
  <joint
    name="Shin4_Joint"
    type="continuous">
    <origin
      xyz="0 -0.058914 0"
      rpy="1.5708 0 -1.8089" />
    <parent
      link="Thigh4_Link" />
    <child
      link="Shin4_Link" />
    <axis
      xyz="0.9718 0 -0.23582" />
  </joint>
  <link
    name="Foot4_Link">
    <inertial>
      <origin
        xyz="0.0036763 0.12771 0.00015874"
        rpy="0 0 0" />
      <mass
        value="0.0091406" />
      <inertia
        ixx="1.4339E-06"
        ixy="6.6635E-08"
        ixz="-7.4416E-13"
        iyy="7.4197E-07"
        iyz="-1.0998E-13"
        izz="1.335E-06" />
    </inertial>
    <visual>
      <origin
        xyz="0 0 0"
        rpy="0 0 0" />
      <geometry>
        <mesh
          filename="package://FullAssemV2_URDF_6/meshes/Foot4_Link.STL" />
      </geometry>
      <material
        name="">
        <color
          rgba="0.79216 0.81961 0.93333 1" />
      </material>
    </visual>
    <collision>
      <origin
        xyz="0 0 0"
        rpy="0 0 0" />
      <geometry>
        <mesh
          filename="package://FullAssemV2_URDF_6/meshes/Foot4_Link.STL" />
      </geometry>
    </collision>
  </link>
  <joint
    name="Foot4_Joint"
    type="continuous">
    <origin
      xyz="0 0 0"
      rpy="1.5708 -0.23806 3.1416" />
    <parent
      link="Shin4_Link" />
    <child
      link="Foot4_Link" />
    <axis
      xyz="1 0 0" />
  </joint>
</robot>