<?xml version="1.0" encoding="utf-8"?>
<!-- This URDF was automatically created by SolidWorks to URDF Exporter! Originally created by Stephen Brawner (brawner@gmail.com) 
     Commit Version: 1.5.1-0-g916b5db  Build Version: 1.5.7152.31018
     For more information, please see http://wiki.ros.org/sw_urdf_exporter -->
<robot
  name="FullAssemV2_URDF_3">
  <link
    name="Quadruped">
    <inertial>
      <origin
        xyz="-0.00015378464630996 0.00598310205159659 0.00185432948237904"
        rpy="0 0 0" />
      <mass
        value="0.249804699601231" />
      <inertia
        ixx="0.000270520719875212"
        ixy="-2.90321355093228E-06"
        ixz="9.97177408530921E-07"
        iyy="0.000561265997940236"
        iyz="-1.82799360298991E-06"
        izz="0.000296712584977651" />
    </inertial>
    <visual>
      <origin
        xyz="0 0 0"
        rpy="0 0 0" />
      <geometry>
        <mesh
          filename="package://FullAssemV2_URDF_3/meshes/Quadruped.STL" />
      </geometry>
      <material
        name="">
        <color
          rgba="0.752941176470588 0.752941176470588 0.752941176470588 1" />
      </material>
    </visual>
    <collision>
      <origin
        xyz="0 0 0"
        rpy="0 0 0" />
      <geometry>
        <mesh
          filename="package://FullAssemV2_URDF_3/meshes/Quadruped.STL" />
      </geometry>
    </collision>
  </link>
  <link
    name="Thigh1_Link">
    <inertial>
      <origin
        xyz="-0.0545698403005456 0.0146554345597752 0.00291630819191364"
        rpy="0 0 0" />
      <mass
        value="0.0539963779122503" />
      <inertia
        ixx="1.29584423628135E-05"
        ixy="6.67024632526158E-06"
        ixz="-2.61236518773455E-08"
        iyy="2.291933315844E-05"
        iyz="-2.81821887768504E-08"
        izz="2.49843294571438E-05" />
    </inertial>
    <visual>
      <origin
        xyz="0 0 0"
        rpy="0 0 0" />
      <geometry>
        <mesh
          filename="package://FullAssemV2_URDF_3/meshes/Thigh1_Link.STL" />
      </geometry>
      <material
        name="">
        <color
          rgba="0.752941176470588 0.752941176470588 0.752941176470588 1" />
      </material>
    </visual>
    <collision>
      <origin
        xyz="0 0 0"
        rpy="0 0 0" />
      <geometry>
        <mesh
          filename="package://FullAssemV2_URDF_3/meshes/Thigh1_Link.STL" />
      </geometry>
    </collision>
  </link>
  <joint
    name="Thigh1_Joint"
    type="continuous">
    <origin
      xyz="-0.0390654999999987 -0.0538815367264155 0"
      rpy="1.5707963267949 0 0.0988146875234264" />
    <parent
      link="Quadruped" />
    <child
      link="Thigh1_Link" />
    <axis
      xyz="0 1 0" />
  </joint>
  <link
    name="Shin1_Link">
    <inertial>
      <origin
        xyz="0.0892929753913887 0.000524244558547986 0.124070762240656"
        rpy="0 0 0" />
      <mass
        value="0.0578934425503477" />
      <inertia
        ixx="5.19105333051062E-06"
        ixy="-1.68835425081224E-07"
        ixz="-2.1134891416634E-06"
        iyy="9.84784531286188E-05"
        iyz="-1.0816772532208E-08"
        izz="9.48222239939683E-05" />
    </inertial>
    <visual>
      <origin
        xyz="0 0 0"
        rpy="0 0 0" />
      <geometry>
        <mesh
          filename="package://FullAssemV2_URDF_3/meshes/Shin1_Link.STL" />
      </geometry>
      <material
        name="">
        <color
          rgba="0.752941176470588 0.752941176470588 0.752941176470588 1" />
      </material>
    </visual>
    <collision>
      <origin
        xyz="0 0 0"
        rpy="0 0 0" />
      <geometry>
        <mesh
          filename="package://FullAssemV2_URDF_3/meshes/Shin1_Link.STL" />
      </geometry>
    </collision>
  </link>
  <joint
    name="Shin1_Joint"
    type="continuous">
    <origin
      xyz="0 0.0782262384375112 0"
      rpy="1.5707963267949 0 -1.65926745961856" />
    <parent
      link="Thigh1_Link" />
    <child
      link="Shin1_Link" />
    <axis
      xyz="0.996088981335105 0 -0.0883557653059113" />
  </joint>
  <link
    name="Foot1_Link">
    <inertial>
      <origin
        xyz="-0.0217799060111764 0.141583392875683 0.000158750645011599"
        rpy="0 0 0" />
      <mass
        value="0.00914057897642937" />
      <inertia
        ixx="1.43388059300199E-06"
        ixy="6.66353810967667E-08"
        ixz="1.9161612405122E-14"
        iyy="7.41969158641372E-07"
        iyz="-1.28331133284468E-13"
        izz="1.33502935768451E-06" />
    </inertial>
    <visual>
      <origin
        xyz="0 0 0"
        rpy="0 0 0" />
      <geometry>
        <mesh
          filename="package://FullAssemV2_URDF_3/meshes/Foot1_Link.STL" />
      </geometry>
      <material
        name="">
        <color
          rgba="0.792156862745098 0.819607843137255 0.933333333333333 1" />
      </material>
    </visual>
    <collision>
      <origin
        xyz="0 0 0"
        rpy="0 0 0" />
      <geometry>
        <mesh
          filename="package://FullAssemV2_URDF_3/meshes/Foot1_Link.STL" />
      </geometry>
    </collision>
  </link>
  <joint
    name="foot1_Joint"
    type="continuous">
    <origin
      xyz="0.151338456248319 0 -0.0134241271338217"
      rpy="1.5707963267949 -0.0884711328236603 -3.14159265358979" />
    <parent
      link="Shin1_Link" />
    <child
      link="Foot1_Link" />
    <axis
      xyz="1 0 0" />
  </joint>
  <link
    name="Thigh2_Link">
    <inertial>
      <origin
        xyz="-0.0428381394799166 0.0254412669047211 0.00291630750864779"
        rpy="0 0 0" />
      <mass
        value="0.0539963748679672" />
      <inertia
        ixx="2.40390969188525E-05"
        ixy="5.73769477599079E-06"
        ixz="-2.63824185804164E-08"
        iyy="1.18386784033394E-05"
        iyz="-2.84200309366262E-08"
        izz="2.49843293303803E-05" />
    </inertial>
    <visual>
      <origin
        xyz="0 0 0"
        rpy="0 0 0" />
      <geometry>
        <mesh
          filename="package://FullAssemV2_URDF_3/meshes/Thigh2_Link.STL" />
      </geometry>
      <material
        name="">
        <color
          rgba="0.752941176470588 0.752941176470588 0.752941176470588 1" />
      </material>
    </visual>
    <collision>
      <origin
        xyz="0 0 0"
        rpy="0 0 0" />
      <geometry>
        <mesh
          filename="package://FullAssemV2_URDF_3/meshes/Thigh2_Link.STL" />
      </geometry>
    </collision>
  </link>
  <joint
    name="Thigh2_Joint"
    type="continuous">
    <origin
      xyz="0.0390654999999996 -0.0538815367264143 0"
      rpy="1.57079632679491 0 2.27816521599251" />
    <parent
      link="Quadruped" />
    <child
      link="Thigh2_Link" />
    <axis
      xyz="0 1 0" />
  </joint>
  <link
    name="Shin2_Link">
    <inertial>
      <origin
        xyz="-0.0296585383581865 0.000524244208756353 0.135544012679483"
        rpy="0 0 0" />
      <mass
        value="0.0578934415393017" />
      <inertia
        ixx="5.18978395918255E-06"
        ixy="-1.68960441980538E-07"
        ixz="-2.11274764913103E-06"
        iyy="9.84784530745943E-05"
        iyz="-1.08885281612082E-08"
        izz="9.4823493254292E-05" />
    </inertial>
    <visual>
      <origin
        xyz="0 0 0"
        rpy="0 0 0" />
      <geometry>
        <mesh
          filename="package://FullAssemV2_URDF_3/meshes/Shin2_Link.STL" />
      </geometry>
      <material
        name="">
        <color
          rgba="0.752941176470588 0.752941176470588 0.752941176470588 1" />
      </material>
    </visual>
    <collision>
      <origin
        xyz="0 0 0"
        rpy="0 0 0" />
      <geometry>
        <mesh
          filename="package://FullAssemV2_URDF_3/meshes/Shin2_Link.STL" />
      </geometry>
    </collision>
  </link>
  <joint
    name="Shin2_Joint"
    type="continuous">
    <origin
      xyz="0 -0.0409367652139851 0"
      rpy="1.57079632679491 0 -2.0949535069755" />
    <parent
      link="Thigh2_Link" />
    <child
      link="Shin2_Link" />
    <axis
      xyz="0.865746066487659 0 -0.500483514574801" />
  </joint>
  <link
    name="Foot2_Link">
    <inertial>
      <origin
        xyz="0.00616011444947555 0.147432131326342 0.000158758883308144"
        rpy="0 0 0" />
      <mass
        value="0.00914057905747706" />
      <inertia
        ixx="1.43388058850935E-06"
        ixy="6.66354888171241E-08"
        ixz="9.08725544711791E-14"
        iyy="7.41969157898052E-07"
        iyz="-1.18456942251138E-13"
        izz="1.33502935366218E-06" />
    </inertial>
    <visual>
      <origin
        xyz="0 0 0"
        rpy="0 0 0" />
      <geometry>
        <mesh
          filename="package://FullAssemV2_URDF_3/meshes/Foot2_Link.STL" />
      </geometry>
      <material
        name="">
        <color
          rgba="0.792156862745098 0.819607843137255 0.933333333333333 1" />
      </material>
    </visual>
    <collision>
      <origin
        xyz="0 0 0"
        rpy="0 0 0" />
      <geometry>
        <mesh
          filename="package://FullAssemV2_URDF_3/meshes/Foot2_Link.STL" />
      </geometry>
    </collision>
  </link>
  <joint
    name="Foot2_Joint"
    type="continuous">
    <origin
      xyz="-0.00218582451977871 0 0.0012636143324808"
      rpy="1.57079632679492 -0.524157180180599 3.14159265358976" />
    <parent
      link="Shin2_Link" />
    <child
      link="Foot2_Link" />
    <axis
      xyz="1 0 0" />
  </joint>
  <link
    name="Thigh3_Link">
    <inertial>
      <origin
        xyz="-0.0504817349530855 0.020372992496018 0.00291630787451894"
        rpy="0 0 0" />
      <mass
        value="0.0539963764838059" />
      <inertia
        ixx="1.78639062225316E-05"
        ixy="8.34687134477563E-06"
        ixz="-2.6213829505366E-08"
        iyy="1.80138692073677E-05"
        iyz="-2.83082688021049E-08"
        izz="2.49843294028074E-05" />
    </inertial>
    <visual>
      <origin
        xyz="0 0 0"
        rpy="0 0 0" />
      <geometry>
        <mesh
          filename="package://FullAssemV2_URDF_3/meshes/Thigh3_Link.STL" />
      </geometry>
      <material
        name="">
        <color
          rgba="0.752941176470588 0.752941176470588 0.752941176470588 1" />
      </material>
    </visual>
    <collision>
      <origin
        xyz="0 0 0"
        rpy="0 0 0" />
      <geometry>
        <mesh
          filename="package://FullAssemV2_URDF_3/meshes/Thigh3_Link.STL" />
      </geometry>
    </collision>
  </link>
  <joint
    name="Thigh3_Joint"
    type="continuous">
    <origin
      xyz="0.0394334999999994 0.0534799999999998 0"
      rpy="1.57079632679491 0 -2.78379592383675" />
    <parent
      link="Quadruped" />
    <child
      link="Thigh3_Link" />
    <axis
      xyz="0 1 0" />
  </joint>
  <link
    name="Shin3_Link">
    <inertial>
      <origin
        xyz="-0.0175951991522868 0.000524244133661318 0.161105964255909"
        rpy="0 0 0" />
      <mass
        value="0.0578934409646989" />
      <inertia
        ixx="5.19137301232651E-06"
        ixy="-1.68786390731139E-07"
        ixz="-2.11391528844394E-06"
        iyy="9.84784530531228E-05"
        iyz="-1.08004114953346E-08"
        izz="9.48219041863955E-05" />
    </inertial>
    <visual>
      <origin
        xyz="0 0 0"
        rpy="0 0 0" />
      <geometry>
        <mesh
          filename="package://FullAssemV2_URDF_3/meshes/Shin3_Link.STL" />
      </geometry>
      <material
        name="">
        <color
          rgba="0.752941176470588 0.752941176470588 0.752941176470588 1" />
      </material>
    </visual>
    <collision>
      <origin
        xyz="0 0 0"
        rpy="0 0 0" />
      <geometry>
        <mesh
          filename="package://FullAssemV2_URDF_3/meshes/Shin3_Link.STL" />
      </geometry>
    </collision>
  </link>
  <joint
    name="Shin3_Joint"
    type="continuous">
    <origin
      xyz="0 -0.0617384132830123 0"
      rpy="1.5707963267949 0 -2.08009224333623" />
    <parent
      link="Thigh3_Link" />
    <child
      link="Shin3_Link" />
    <axis
      xyz="0.873088008817442 0 -0.487562640959286" />
  </joint>
  <link
    name="Foot3_Link">
    <inertial>
      <origin
        xyz="0.00616011511678777 0.175922028789006 0.000158757316407208"
        rpy="0 0 0" />
      <mass
        value="0.00914057903727103" />
      <inertia
        ixx="1.43388054325383E-06"
        ixy="6.6635469140512E-08"
        ixz="4.07491870127514E-13"
        iyy="7.41969110605252E-07"
        iyz="-1.34870054994751E-13"
        izz="1.33502935775728E-06" />
    </inertial>
    <visual>
      <origin
        xyz="0 0 0"
        rpy="0 0 0" />
      <geometry>
        <mesh
          filename="package://FullAssemV2_URDF_3/meshes/Foot3_Link.STL" />
      </geometry>
      <material
        name="">
        <color
          rgba="0.792156862745098 0.819607843137255 0.933333333333333 1" />
      </material>
    </visual>
    <collision>
      <origin
        xyz="0 0 0"
        rpy="0 0 0" />
      <geometry>
        <mesh
          filename="package://FullAssemV2_URDF_3/meshes/Foot3_Link.STL" />
      </geometry>
    </collision>
  </link>
  <joint
    name="Foot3_Joint"
    type="continuous">
    <origin
      xyz="-0.00201007945197229 0 0.00112249811730789"
      rpy="1.57079632679489 -0.509295916541321 3.14159265358979" />
    <parent
      link="Shin3_Link" />
    <child
      link="Foot3_Link" />
    <axis
      xyz="1 0 0" />
  </joint>
  <link
    name="Thigh4_Link">
    <inertial>
      <origin
        xyz="-0.0462619802859904 0.0237250553433097 0.00291630755020896"
        rpy="0 0 0" />
      <mass
        value="0.0539963752533572" />
      <inertia
        ixx="2.17558165409712E-05"
        ixy="7.44301495861805E-06"
        ixz="-2.63069177494671E-08"
        iyy="1.41219587840874E-05"
        iyz="-2.83821856933605E-08"
        izz="2.49843293351259E-05" />
    </inertial>
    <visual>
      <origin
        xyz="0 0 0"
        rpy="0 0 0" />
      <geometry>
        <mesh
          filename="package://FullAssemV2_URDF_3/meshes/Thigh4_Link.STL" />
      </geometry>
      <material
        name="">
        <color
          rgba="0.752941176470588 0.752941176470588 0.752941176470588 1" />
      </material>
    </visual>
    <collision>
      <origin
        xyz="0 0 0"
        rpy="0 0 0" />
      <geometry>
        <mesh
          filename="package://FullAssemV2_URDF_3/meshes/Thigh4_Link.STL" />
      </geometry>
    </collision>
  </link>
  <joint
    name="Thigh4_Joint"
    type="continuous">
    <origin
      xyz="-0.0394334999999997 0.053479999999999 0"
      rpy="1.5707963267949 0 -0.472568821474213" />
    <parent
      link="Quadruped" />
    <child
      link="Thigh4_Link" />
    <axis
      xyz="0 1 0" />
  </joint>
  <link
    name="Shin4_Link">
    <inertial>
      <origin
        xyz="-0.0698472098485315 0.000524248300828239 0.125150424787107"
        rpy="0 0 0" />
      <mass
        value="0.0578934415141883" />
      <inertia
        ixx="5.18920740671184E-06"
        ixy="-1.69002634607576E-07"
        ixz="-2.11267767615982E-06"
        iyy="9.84784530913175E-05"
        iyz="-1.0925956967824E-08"
        izz="9.48240698489554E-05" />
    </inertial>
    <visual>
      <origin
        xyz="0 0 0"
        rpy="0 0 0" />
      <geometry>
        <mesh
          filename="package://FullAssemV2_URDF_3/meshes/Shin4_Link.STL" />
      </geometry>
      <material
        name="">
        <color
          rgba="0.752941176470588 0.752941176470588 0.752941176470588 1" />
      </material>
    </visual>
    <collision>
      <origin
        xyz="0 0 0"
        rpy="0 0 0" />
      <geometry>
        <mesh
          filename="package://FullAssemV2_URDF_3/meshes/Shin4_Link.STL" />
      </geometry>
    </collision>
  </link>
  <joint
    name="Shin4_Joint"
    type="continuous">
    <origin
      xyz="0 -0.0589139946836245 0"
      rpy="1.5707963267949 0 -1.8088561420647" />
    <parent
      link="Thigh4_Link" />
    <child
      link="Shin4_Link" />
    <axis
      xyz="0.971797333357456 0 -0.235817605108987" />
  </joint>
  <link
    name="Foot4_Link">
    <inertial>
      <origin
        xyz="0.00616013961085539 0.127708470173728 0.000158743643449085"
        rpy="0 0 0" />
      <mass
        value="0.00914057907848054" />
      <inertia
        ixx="1.43388047627197E-06"
        ixy="6.66354983920582E-08"
        ixz="-7.44155415428041E-13"
        iyy="7.41969046146568E-07"
        iyz="-1.09981926780573E-13"
        izz="1.33502934802945E-06" />
    </inertial>
    <visual>
      <origin
        xyz="0 0 0"
        rpy="0 0 0" />
      <geometry>
        <mesh
          filename="package://FullAssemV2_URDF_3/meshes/Foot4_Link.STL" />
      </geometry>
      <material
        name="">
        <color
          rgba="0.792156862745098 0.819607843137255 0.933333333333333 1" />
      </material>
    </visual>
    <collision>
      <origin
        xyz="0 0 0"
        rpy="0 0 0" />
      <geometry>
        <mesh
          filename="package://FullAssemV2_URDF_3/meshes/Foot4_Link.STL" />
      </geometry>
    </collision>
  </link>
  <joint
    name="Foot4_Joint"
    type="continuous">
    <origin
      xyz="0.00241374299128982 0 -0.000585722014268167"
      rpy="1.5707963267949 -0.238059815269797 3.14159265358978" />
    <parent
      link="Shin4_Link" />
    <child
      link="Foot4_Link" />
    <axis
      xyz="1 0 0" />
  </joint>
</robot>