<?xml version="1.0" encoding="utf-8"?>
<!-- This URDF was automatically created by SolidWorks to URDF Exporter! Originally created by Stephen Brawner (brawner@gmail.com) 
     Commit Version: 1.5.1-0-g916b5db  Build Version: 1.5.7152.31018
     For more information, please see http://wiki.ros.org/sw_urdf_exporter -->
<robot
  name="FullAssemV2_URDF_8">
  <link
    name="Base_Link">
    <inertial>
      <origin
        xyz="-0.00017976 0.0064014 0.0017348"
        rpy="0 0 0" />
      <mass
        value="0.21236" />
      <inertia
        ixx="0.00026919"
        ixy="-2.9034E-06"
        ixz="9.9958E-07"
        iyy="0.00055913"
        iyz="-1.8533E-06"
        izz="0.00029537" />
    </inertial>
    <visual>
      <origin
        xyz="0 0 0"
        rpy="0 0 0" />
      <geometry>
        <mesh
          filename="package://FullAssemV2_URDF_8/meshes/Base_Link.STL" />
      </geometry>
      <material
        name="">
        <color
          rgba="0.79216 0.81961 0.93333 1" />
      </material>
    </visual>
    <collision>
      <origin
        xyz="0 0 0"
        rpy="0 0 0" />
      <geometry>
        <mesh
          filename="package://FullAssemV2_URDF_8/meshes/Base_Link.STL" />
      </geometry>
    </collision>
  </link>
  <link
    name="Hip4_Link">
    <inertial>
      <origin
        xyz="-0.011761 -0.0029717 -0.015857"
        rpy="0 0 0" />
      <mass
        value="0.026582" />
      <inertia
        ixx="6.5375E-06"
        ixy="1.1094E-08"
        ixz="-1.2634E-06"
        iyy="4.1152E-06"
        iyz="-1.4967E-08"
        izz="5.1173E-06" />
    </inertial>
    <visual>
      <origin
        xyz="0 0 0"
        rpy="0 0 0" />
      <geometry>
        <mesh
          filename="package://FullAssemV2_URDF_8/meshes/Hip4_Link.STL" />
      </geometry>
      <material
        name="">
        <color
          rgba="0.79216 0.81961 0.93333 1" />
      </material>
    </visual>
    <collision>
      <origin
        xyz="0 0 0"
        rpy="0 0 0" />
      <geometry>
        <mesh
          filename="package://FullAssemV2_URDF_8/meshes/Hip4_Link.STL" />
      </geometry>
    </collision>
  </link>
  <joint
    name="Hip4_Joint"
    type="fixed">
    <origin
      xyz="-0.039434 0.04833 0.0012"
      rpy="-1.5708 0 -1.5708" />
    <parent
      link="Base_Link" />
    <child
      link="Hip4_Link" />
    <axis
      xyz="0 0 0" />
  </joint>
  <link
    name="Thigh4_Link">
    <inertial>
      <origin
        xyz="-0.059271 -0.0091138 0.036281"
        rpy="0 0 0" />
      <mass
        value="0.036775" />
      <inertia
        ixx="5.8897E-06"
        ixy="7.1143E-09"
        ixz="1.3761E-07"
        iyy="1.7963E-05"
        iyz="-1.0798E-08"
        izz="2.2441E-05" />
    </inertial>
    <visual>
      <origin
        xyz="0 0 0"
        rpy="0 0 0" />
      <geometry>
        <mesh
          filename="package://FullAssemV2_URDF_8/meshes/Thigh4_Link.STL" />
      </geometry>
      <material
        name="">
        <color
          rgba="0.79216 0.81961 0.93333 1" />
      </material>
    </visual>
    <collision>
      <origin
        xyz="0 0 0"
        rpy="0 0 0" />
      <geometry>
        <mesh
          filename="package://FullAssemV2_URDF_8/meshes/Thigh4_Link.STL" />
      </geometry>
    </collision>
  </link>
  <joint
    name="Thigh4_Joint"
    type="continuous">
    <origin
      xyz="0.01 0 0"
      rpy="-2.6013 -0.48447 1.2984" />
    <parent
      link="Hip4_Link" />
    <child
      link="Thigh4_Link" />
    <axis
      xyz="0.85229 0 0.52306" />
  </joint>
  <link
    name="Shin4_Link">
    <inertial>
      <origin
        xyz="-0.069847 0.00052424 0.12515"
        rpy="0 0 0" />
      <mass
        value="0.057893" />
      <inertia
        ixx="5.1892E-06"
        ixy="-1.69E-07"
        ixz="-2.1127E-06"
        iyy="9.8478E-05"
        iyz="-1.0926E-08"
        izz="9.4824E-05" />
    </inertial>
    <visual>
      <origin
        xyz="0 0 0"
        rpy="0 0 0" />
      <geometry>
        <mesh
          filename="package://FullAssemV2_URDF_8/meshes/Shin4_Link.STL" />
      </geometry>
      <material
        name="">
        <color
          rgba="0.75294 0.75294 0.75294 1" />
      </material>
    </visual>
    <collision>
      <origin
        xyz="0 0 0"
        rpy="0 0 0" />
      <geometry>
        <mesh
          filename="package://FullAssemV2_URDF_8/meshes/Shin4_Link.STL" />
      </geometry>
    </collision>
  </link>
  <joint
    name="Shin4_Joint"
    type="continuous">
    <origin
      xyz="0.047628 -0.01349 0.037321"
      rpy="0 -0.7885 0" />
    <parent
      link="Thigh4_Link" />
    <child
      link="Shin4_Link" />
    <axis
      xyz="0.9718 0 -0.23582" />
  </joint>
  <link
    name="Foot4_Link">
    <inertial>
      <origin
        xyz="0.0036762 0.12771 0.00015874"
        rpy="0 0 0" />
      <mass
        value="0.0091406" />
      <inertia
        ixx="1.4339E-06"
        ixy="6.6635E-08"
        ixz="-7.4416E-13"
        iyy="7.4197E-07"
        iyz="-1.0998E-13"
        izz="1.335E-06" />
    </inertial>
    <visual>
      <origin
        xyz="0 0 0"
        rpy="0 0 0" />
      <geometry>
        <mesh
          filename="package://FullAssemV2_URDF_8/meshes/Foot4_Link.STL" />
      </geometry>
      <material
        name="">
        <color
          rgba="0.79216 0.81961 0.93333 1" />
      </material>
    </visual>
    <collision>
      <origin
        xyz="0 0 0"
        rpy="0 0 0" />
      <geometry>
        <mesh
          filename="package://FullAssemV2_URDF_8/meshes/Foot4_Link.STL" />
      </geometry>
    </collision>
  </link>
  <joint
    name="Foot4_Joint"
    type="continuous">
    <origin
      xyz="0 0 0"
      rpy="1.5708 -0.23806 3.1416" />
    <parent
      link="Shin4_Link" />
    <child
      link="Foot4_Link" />
    <axis
      xyz="1 0 0" />
  </joint>
  <link
    name="Hip3_Link">
    <inertial>
      <origin
        xyz="-0.0096475 -0.0029717 0.016789"
        rpy="0 0 0" />
      <mass
        value="0.026582" />
      <inertia
        ixx="6.8538E-06"
        ixy="-3.974E-08"
        ixz="9.7439E-07"
        iyy="4.1152E-06"
        iyz="-7.4494E-09"
        izz="4.801E-06" />
    </inertial>
    <visual>
      <origin
        xyz="0 0 0"
        rpy="0 0 0" />
      <geometry>
        <mesh
          filename="package://FullAssemV2_URDF_8/meshes/Hip3_Link.STL" />
      </geometry>
      <material
        name="">
        <color
          rgba="0.75294 0.75294 0.75294 1" />
      </material>
    </visual>
    <collision>
      <origin
        xyz="0 0 0"
        rpy="0 0 0" />
      <geometry>
        <mesh
          filename="package://FullAssemV2_URDF_8/meshes/Hip3_Link.STL" />
      </geometry>
    </collision>
  </link>
  <joint
    name="Hip3_Joint"
    type="fixed">
    <origin
      xyz="0.039434 0.04833 0.0012"
      rpy="-1.5708 0 -1.5708" />
    <parent
      link="Base_Link" />
    <child
      link="Hip3_Link" />
    <axis
      xyz="0 0 0" />
  </joint>
  <link
    name="Thigh3_Link">
    <inertial>
      <origin
        xyz="-0.066054 0.018566 0.027776"
        rpy="0 0 0" />
      <mass
        value="0.036775" />
      <inertia
        ixx="5.8177E-06"
        ixy="9.5065E-09"
        ixz="1.543E-07"
        iyy="1.7963E-05"
        iyz="-8.8988E-09"
        izz="2.2513E-05" />
    </inertial>
    <visual>
      <origin
        xyz="0 0 0"
        rpy="0 0 0" />
      <geometry>
        <mesh
          filename="package://FullAssemV2_URDF_8/meshes/Thigh3_Link.STL" />
      </geometry>
      <material
        name="">
        <color
          rgba="0.79216 0.81961 0.93333 1" />
      </material>
    </visual>
    <collision>
      <origin
        xyz="0 0 0"
        rpy="0 0 0" />
      <geometry>
        <mesh
          filename="package://FullAssemV2_URDF_8/meshes/Thigh3_Link.STL" />
      </geometry>
    </collision>
  </link>
  <joint
    name="Thigh3_Joint"
    type="continuous">
    <origin
      xyz="0.01 0 0"
      rpy="-0.48921 0.7299 1.2297" />
    <parent
      link="Hip3_Link" />
    <child
      link="Thigh3_Link" />
    <axis
      xyz="0.70231 0 0.71188" />
  </joint>
  <link
    name="Shin3_Link">
    <inertial>
      <origin
        xyz="-0.017595 0.00052424 0.16111"
        rpy="0 0 0" />
      <mass
        value="0.057893" />
      <inertia
        ixx="5.1914E-06"
        ixy="-1.6879E-07"
        ixz="-2.1139E-06"
        iyy="9.8478E-05"
        iyz="-1.08E-08"
        izz="9.4822E-05" />
    </inertial>
    <visual>
      <origin
        xyz="0 0 0"
        rpy="0 0 0" />
      <geometry>
        <mesh
          filename="package://FullAssemV2_URDF_8/meshes/Shin3_Link.STL" />
      </geometry>
      <material
        name="">
        <color
          rgba="0.75294 0.75294 0.75294 1" />
      </material>
    </visual>
    <collision>
      <origin
        xyz="0 0 0"
        rpy="0 0 0" />
      <geometry>
        <mesh
          filename="package://FullAssemV2_URDF_8/meshes/Shin3_Link.STL" />
      </geometry>
    </collision>
  </link>
  <joint
    name="Shin3_Joint"
    type="continuous">
    <origin
      xyz="0.040425 0.014191 0.048531"
      rpy="0 -1.3015 0" />
    <parent
      link="Thigh3_Link" />
    <child
      link="Shin3_Link" />
    <axis
      xyz="0.87309 0 -0.48756" />
  </joint>
  <link
    name="Foot3_Link">
    <inertial>
      <origin
        xyz="0.00846236937903797 0.175922186726946 0.000158755831628617"
        rpy="0 0 0" />
      <mass
        value="0.00914057903727103" />
      <inertia
        ixx="1.43388054325383E-06"
        ixy="6.66354691405123E-08"
        ixz="4.07491869839655E-13"
        iyy="7.41969110605252E-07"
        iyz="-1.34870054650644E-13"
        izz="1.33502935775728E-06" />
    </inertial>
    <visual>
      <origin
        xyz="0 0 0"
        rpy="0 0 0" />
      <geometry>
        <mesh
          filename="package://FullAssemV2_URDF_8/meshes/Foot3_Link.STL" />
      </geometry>
      <material
        name="">
        <color
          rgba="0.792156862745098 0.819607843137255 0.933333333333333 1" />
      </material>
    </visual>
    <collision>
      <origin
        xyz="0 0 0"
        rpy="0 0 0" />
      <geometry>
        <mesh
          filename="package://FullAssemV2_URDF_8/meshes/Foot3_Link.STL" />
      </geometry>
    </collision>
  </link>
  <joint
    name="Foot3_Joint"
    type="continuous">
    <origin
      xyz="0 0 0"
      rpy="1.5707963267949 -0.509295916609659 3.14159265358979" />
    <parent
      link="Shin3_Link" />
    <child
      link="Foot3_Link" />
    <axis
      xyz="1 0 0" />
  </joint>
  <link
    name="Hip2_Link">
    <inertial>
      <origin
        xyz="-0.015026 0.0029717 -0.013671"
        rpy="0 0 0" />
      <mass
        value="0.026582" />
      <inertia
        ixx="5.9497E-06"
        ixy="3.5553E-08"
        ixz="-1.5056E-06"
        iyy="4.1152E-06"
        iyz="-1.6272E-08"
        izz="5.7051E-06" />
    </inertial>
    <visual>
      <origin
        xyz="0 0 0"
        rpy="0 0 0" />
      <geometry>
        <mesh
          filename="package://FullAssemV2_URDF_8/meshes/Hip2_Link.STL" />
      </geometry>
      <material
        name="">
        <color
          rgba="0.75294 0.75294 0.75294 1" />
      </material>
    </visual>
    <collision>
      <origin
        xyz="0 0 0"
        rpy="0 0 0" />
      <geometry>
        <mesh
          filename="package://FullAssemV2_URDF_8/meshes/Hip2_Link.STL" />
      </geometry>
    </collision>
  </link>
  <joint
    name="Hip2_Joint"
    type="fixed">
    <origin
      xyz="0.033915 -0.053882 0.0012"
      rpy="1.5708 0 3.1416" />
    <parent
      link="Base_Link" />
    <child
      link="Hip2_Link" />
    <axis
      xyz="0 0 0" />
  </joint>
  <link
    name="Thigh2_Link">
    <inertial>
      <origin
        xyz="-0.0548800061707602 0.0043757653956759 0.0319698371469879"
        rpy="0 0 0" />
      <mass
        value="0.0367745512938791" />
      <inertia
        ixx="5.93189322227311E-06"
        ixy="5.17345146438572E-09"
        ixz="1.06059224556055E-07"
        iyy="1.79630759542792E-05"
        iyz="-1.17696889760325E-08"
        izz="2.23989407765632E-05" />
    </inertial>
    <visual>
      <origin
        xyz="0 0 0"
        rpy="0 0 0" />
      <geometry>
        <mesh
          filename="package://FullAssemV2_URDF_8/meshes/Thigh2_Link.STL" />
      </geometry>
      <material
        name="">
        <color
          rgba="0.792156862745098 0.819607843137255 0.933333333333333 1" />
      </material>
    </visual>
    <collision>
      <origin
        xyz="0 0 0"
        rpy="0 0 0" />
      <geometry>
        <mesh
          filename="package://FullAssemV2_URDF_8/meshes/Thigh2_Link.STL" />
      </geometry>
    </collision>
  </link>
  <joint
    name="Thigh2_Joint"
    type="continuous">
    <origin
      xyz="-0.00515 -0.0051047 0"
      rpy="2.3977 -0.28496 -1.3177" />
    <parent
      link="Hip2_Link" />
    <child
      link="Thigh2_Link" />
    <axis
      xyz="0.92909 0 0.36986" />
  </joint>
  <link
    name="Shin2_Link">
    <inertial>
      <origin
        xyz="-0.029659 0.00052424 0.13554"
        rpy="0 0 0" />
      <mass
        value="0.057893" />
      <inertia
        ixx="5.1898E-06"
        ixy="-1.6896E-07"
        ixz="-2.1127E-06"
        iyy="9.8478E-05"
        iyz="-1.0889E-08"
        izz="9.4823E-05" />
    </inertial>
    <visual>
      <origin
        xyz="0 0 0"
        rpy="0 0 0" />
      <geometry>
        <mesh
          filename="package://FullAssemV2_URDF_8/meshes/Shin2_Link.STL" />
      </geometry>
      <material
        name="">
        <color
          rgba="0.75294 0.75294 0.75294 1" />
      </material>
    </visual>
    <collision>
      <origin
        xyz="0 0 0"
        rpy="0 0 0" />
      <geometry>
        <mesh
          filename="package://FullAssemV2_URDF_8/meshes/Shin2_Link.STL" />
      </geometry>
    </collision>
  </link>
  <joint
    name="Shin2_Joint"
    type="continuous">
    <origin
      xyz="0.034406 0 0.013697"
      rpy="0 -0.90302 0" />
    <parent
      link="Thigh2_Link" />
    <child
      link="Shin2_Link" />
    <axis
      xyz="0.86575 0 -0.50048" />
  </joint>
  <link
    name="Foot2_Link">
    <inertial>
      <origin
        xyz="0.0086849 0.14743 0.00015875"
        rpy="0 0 0" />
      <mass
        value="0.0091406" />
      <inertia
        ixx="1.4339E-06"
        ixy="6.6635E-08"
        ixz="9.0873E-14"
        iyy="7.4197E-07"
        iyz="-1.1846E-13"
        izz="1.335E-06" />
    </inertial>
    <visual>
      <origin
        xyz="0 0 0"
        rpy="0 0 0" />
      <geometry>
        <mesh
          filename="package://FullAssemV2_URDF_8/meshes/Foot2_Link.STL" />
      </geometry>
      <material
        name="">
        <color
          rgba="0.79216 0.81961 0.93333 1" />
      </material>
    </visual>
    <collision>
      <origin
        xyz="0 0 0"
        rpy="0 0 0" />
      <geometry>
        <mesh
          filename="package://FullAssemV2_URDF_8/meshes/Foot2_Link.STL" />
      </geometry>
    </collision>
  </link>
  <joint
    name="Foot2_Joint"
    type="continuous">
    <origin
      xyz="0 0 0"
      rpy="1.57079632679491 -0.524157180178585 3.14159265358978" />
    <parent
      link="Shin2_Link" />
    <child
      link="Foot2_Link" />
    <axis
      xyz="1 0 0" />
  </joint>
  <link
    name="Hip1_Link">
    <inertial>
      <origin
        xyz="0 0 0"
        rpy="0 0 0" />
      <mass
        value="0" />
      <inertia
        ixx="0"
        ixy="0"
        ixz="0"
        iyy="0"
        iyz="0"
        izz="0" />
    </inertial>
    <visual>
      <origin
        xyz="0 0 0"
        rpy="0 0 0" />
      <geometry>
        <mesh
          filename="package://FullAssemV2_URDF_8/meshes/Hip1_Link.STL" />
      </geometry>
      <material
        name="">
        <color
          rgba="1 1 1 1" />
      </material>
    </visual>
    <collision>
      <origin
        xyz="0 0 0"
        rpy="0 0 0" />
      <geometry>
        <mesh
          filename="package://FullAssemV2_URDF_8/meshes/Hip1_Link.STL" />
      </geometry>
    </collision>
  </link>
  <joint
    name="Hip1_Joint"
    type="fixed">
    <origin
      xyz="-0.033915 -0.053882 0.0012"
      rpy="1.5708 0 0" />
    <parent
      link="Base_Link" />
    <child
      link="Hip1_Link" />
    <axis
      xyz="0 0 0" />
  </joint>
  <link
    name="Thigh1_Link">
    <inertial>
      <origin
        xyz="-0.07059 0.0043758 0.0091001"
        rpy="0 0 0" />
      <mass
        value="0.036775" />
      <inertia
        ixx="5.727E-06"
        ixy="1.1825E-08"
        ixz="1.233E-07"
        iyy="1.7963E-05"
        iyz="-5.6591E-09"
        izz="2.2604E-05" />
    </inertial>
    <visual>
      <origin
        xyz="0 0 0"
        rpy="0 0 0" />
      <geometry>
        <mesh
          filename="package://FullAssemV2_URDF_8/meshes/Thigh1_Link.STL" />
      </geometry>
      <material
        name="">
        <color
          rgba="0.79216 0.81961 0.93333 1" />
      </material>
    </visual>
    <collision>
      <origin
        xyz="0 0 0"
        rpy="0 0 0" />
      <geometry>
        <mesh
          filename="package://FullAssemV2_URDF_8/meshes/Thigh1_Link.STL" />
      </geometry>
    </collision>
  </link>
  <joint
    name="Thigh1_Joint"
    type="continuous">
    <origin
      xyz="-0.00515 -0.0051514 0"
      rpy="1.5266 0.088391 -0.46477" />
    <parent
      link="Hip1_Link" />
    <child
      link="Thigh1_Link" />
    <axis
      xyz="0.44647 0 0.8948" />
  </joint>
  <link
    name="Shin1_Link">
    <inertial>
      <origin
        xyz="0.089293 0.00052424 0.12407"
        rpy="0 0 0" />
      <mass
        value="0.057893" />
      <inertia
        ixx="5.1911E-06"
        ixy="-1.6884E-07"
        ixz="-2.1135E-06"
        iyy="9.8478E-05"
        iyz="-1.0817E-08"
        izz="9.4822E-05" />
    </inertial>
    <visual>
      <origin
        xyz="0 0 0"
        rpy="0 0 0" />
      <geometry>
        <mesh
          filename="package://FullAssemV2_URDF_8/meshes/Shin1_Link.STL" />
      </geometry>
      <material
        name="">
        <color
          rgba="0.75294 0.75294 0.75294 1" />
      </material>
    </visual>
    <collision>
      <origin
        xyz="0 0 0"
        rpy="0 0 0" />
      <geometry>
        <mesh
          filename="package://FullAssemV2_URDF_8/meshes/Shin1_Link.STL" />
      </geometry>
    </collision>
  </link>
  <joint
    name="Shin1_Joint"
    type="continuous">
    <origin
      xyz="-0.0366894131625819 0 -0.0735319135064403"
      rpy="0 -1.19645296325141 0" />
    <parent
      link="Thigh1_Link" />
    <child
      link="Shin1_Link" />
    <axis
      xyz="0.996088981335105 0 -0.0883557653059113" />
  </joint>
  <link
    name="Foot1_Link">
    <inertial>
      <origin
        xyz="-0.02178 0.14158 0.00015875"
        rpy="0 0 0" />
      <mass
        value="0.0091406" />
      <inertia
        ixx="1.4339E-06"
        ixy="6.6635E-08"
        ixz="1.9162E-14"
        iyy="7.4197E-07"
        iyz="-1.2833E-13"
        izz="1.335E-06" />
    </inertial>
    <visual>
      <origin
        xyz="0 0 0"
        rpy="0 0 0" />
      <geometry>
        <mesh
          filename="package://FullAssemV2_URDF_8/meshes/Foot1_Link.STL" />
      </geometry>
      <material
        name="">
        <color
          rgba="0.79216 0.81961 0.93333 1" />
      </material>
    </visual>
    <collision>
      <origin
        xyz="0 0 0"
        rpy="0 0 0" />
      <geometry>
        <mesh
          filename="package://FullAssemV2_URDF_8/meshes/Foot1_Link.STL" />
      </geometry>
    </collision>
  </link>
  <joint
    name="Foot1_Joint"
    type="continuous">
    <origin
      xyz="0.15134 0 -0.013424"
      rpy="1.5708 -0.088471 3.1416" />
    <parent
      link="Shin1_Link" />
    <child
      link="Foot1_Link" />
    <axis
      xyz="1 0 0" />
  </joint>
</robot>