<?xml version="1.0" encoding="utf-8"?>
<!-- This URDF was automatically created by SolidWorks to URDF Exporter! Originally created by Stephen Brawner (brawner@gmail.com) 
     Commit Version: 1.5.1-0-g916b5db  Build Version: 1.5.7152.31018
     For more information, please see http://wiki.ros.org/sw_urdf_exporter -->
<robot
  name="FullAssemV2_URDF_5">
  <link
    name="Base_Link">
    <inertial>
      <origin
        xyz="-0.00017976 0.0064014 0.0017348"
        rpy="0 0 0" />
      <mass
        value="0.21236" />
      <inertia
        ixx="0.00026919"
        ixy="-2.9034E-06"
        ixz="9.9958E-07"
        iyy="0.00055913"
        iyz="-1.8533E-06"
        izz="0.00029537" />
    </inertial>
    <visual>
      <origin
        xyz="0 0 0"
        rpy="0 0 0" />
      <geometry>
        <mesh
          filename="package://FullAssemV2_URDF_5/meshes/Base_Link.STL" />
      </geometry>
      <material
        name="">
        <color
          rgba="0.79216 0.81961 0.93333 1" />
      </material>
    </visual>
    <collision>
      <origin
        xyz="0 0 0"
        rpy="0 0 0" />
      <geometry>
        <mesh
          filename="package://FullAssemV2_URDF_5/meshes/Base_Link.STL" />
      </geometry>
    </collision>
  </link>
  <link
    name="Hip1_Link">
    <inertial>
      <origin
        xyz="-0.016242 0.0041717 3.2178E-05"
        rpy="0 0 0" />
      <mass
        value="0.026582" />
      <inertia
        ixx="4.1458E-06"
        ixy="1.5113E-08"
        ixz="-6.9539E-08"
        iyy="4.1152E-06"
        iyz="-2.6721E-08"
        izz="7.509E-06" />
    </inertial>
    <visual>
      <origin
        xyz="0 0 0"
        rpy="0 0 0" />
      <geometry>
        <mesh
          filename="package://FullAssemV2_URDF_5/meshes/Hip1_Link.STL" />
      </geometry>
      <material
        name="">
        <color
          rgba="0.79216 0.81961 0.93333 1" />
      </material>
    </visual>
    <collision>
      <origin
        xyz="0 0 0"
        rpy="0 0 0" />
      <geometry>
        <mesh
          filename="package://FullAssemV2_URDF_5/meshes/Hip1_Link.STL" />
      </geometry>
    </collision>
  </link>
  <joint
    name="Hip1_Joint"
    type="continuous">
    <origin
      xyz="-0.039065 -0.053882 0"
      rpy="1.5708 0 0.098815" />
    <parent
      link="Base_Link" />
    <child
      link="Hip1_Link" />
    <axis
      xyz="0 1 0" />
  </joint>
  <link
    name="Thigh1_Link">
    <inertial>
      <origin
        xyz="-0.067227 0.0043758 -0.019422"
        rpy="0 0 0" />
      <mass
        value="0.036775" />
      <inertia
        ixx="8.9926E-06"
        ixy="1.3107E-08"
        ixz="-6.6682E-06"
        iyy="1.7963E-05"
        iyz="2.1557E-10"
        izz="1.9338E-05" />
    </inertial>
    <visual>
      <origin
        xyz="0 0 0"
        rpy="0 0 0" />
      <geometry>
        <mesh
          filename="package://FullAssemV2_URDF_5/meshes/Thigh1_Link.STL" />
      </geometry>
      <material
        name="">
        <color
          rgba="0.75294 0.75294 0.75294 1" />
      </material>
    </visual>
    <collision>
      <origin
        xyz="0 0 0"
        rpy="0 0 0" />
      <geometry>
        <mesh
          filename="package://FullAssemV2_URDF_5/meshes/Thigh1_Link.STL" />
      </geometry>
    </collision>
  </link>
  <joint
    name="Thigh1_Joint"
    type="continuous">
    <origin
      xyz="0 0 0"
      rpy="1.5708 0 0" />
    <parent
      link="Hip1_Link" />
    <child
      link="Thigh1_Link" />
    <axis
      xyz="0 0 1" />
  </joint>
  <link
    name="Shin1_Link">
    <inertial>
      <origin
        xyz="0.089293 0.00052424 0.12407"
        rpy="0 0 0" />
      <mass
        value="0.057893" />
      <inertia
        ixx="5.1911E-06"
        ixy="-1.6884E-07"
        ixz="-2.1135E-06"
        iyy="9.8478E-05"
        iyz="-1.0817E-08"
        izz="9.4822E-05" />
    </inertial>
    <visual>
      <origin
        xyz="0 0 0"
        rpy="0 0 0" />
      <geometry>
        <mesh
          filename="package://FullAssemV2_URDF_5/meshes/Shin1_Link.STL" />
      </geometry>
      <material
        name="">
        <color
          rgba="0.75294 0.75294 0.75294 1" />
      </material>
    </visual>
    <collision>
      <origin
        xyz="0 0 0"
        rpy="0 0 0" />
      <geometry>
        <mesh
          filename="package://FullAssemV2_URDF_5/meshes/Shin1_Link.STL" />
      </geometry>
    </collision>
  </link>
  <joint
    name="Shin1_Joint"
    type="continuous">
    <origin
      xyz="0 0 -0.078226"
      rpy="3.1416 -1.4823 -3.1416" />
    <parent
      link="Thigh1_Link" />
    <child
      link="Shin1_Link" />
    <axis
      xyz="0.99609 0 -0.088356" />
  </joint>
  <link
    name="Foot1_Link">
    <inertial>
      <origin
        xyz="-0.02178 0.14158 0.00015875"
        rpy="0 0 0" />
      <mass
        value="0.0091406" />
      <inertia
        ixx="1.4339E-06"
        ixy="6.6635E-08"
        ixz="1.9162E-14"
        iyy="7.4197E-07"
        iyz="-1.2833E-13"
        izz="1.335E-06" />
    </inertial>
    <visual>
      <origin
        xyz="0 0 0"
        rpy="0 0 0" />
      <geometry>
        <mesh
          filename="package://FullAssemV2_URDF_5/meshes/Foot1_Link.STL" />
      </geometry>
      <material
        name="">
        <color
          rgba="0.79216 0.81961 0.93333 1" />
      </material>
    </visual>
    <collision>
      <origin
        xyz="0 0 0"
        rpy="0 0 0" />
      <geometry>
        <mesh
          filename="package://FullAssemV2_URDF_5/meshes/Foot1_Link.STL" />
      </geometry>
    </collision>
  </link>
  <joint
    name="Foot1_Joint"
    type="continuous">
    <origin
      xyz="0.15134 0 -0.013424"
      rpy="1.5708 -0.088471 3.1416" />
    <parent
      link="Shin1_Link" />
    <child
      link="Foot1_Link" />
    <axis
      xyz="1 0 0" />
  </joint>
  <link
    name="Hip2_Link">
    <inertial>
      <origin
        xyz="-0.0168088349472356 0.00417173894349392 -0.00137707456095665"
        rpy="0 0 0" />
      <mass
        value="0.0265823680727401" />
      <inertia
        ixx="4.32105594114124E-06"
        ixy="1.07357436069011E-08"
        ixz="1.13207676517939E-07"
        iyy="4.11519799393497E-06"
        iyz="-3.75968550275868E-08"
        izz="7.33373551277234E-06" />
    </inertial>
    <visual>
      <origin
        xyz="0 0 0"
        rpy="0 0 0" />
      <geometry>
        <mesh
          filename="package://FullAssemV2_URDF_5/meshes/Hip2_Link.STL" />
      </geometry>
      <material
        name="">
        <color
          rgba="0.792156862745098 0.819607843137255 0.933333333333333 1" />
      </material>
    </visual>
    <collision>
      <origin
        xyz="0 0 0"
        rpy="0 0 0" />
      <geometry>
        <mesh
          filename="package://FullAssemV2_URDF_5/meshes/Hip2_Link.STL" />
      </geometry>
    </collision>
  </link>
  <joint
    name="Hip2_Joint"
    type="continuous">
    <origin
      xyz="0.039065 -0.053882 0"
      rpy="1.5708 0 2.2782" />
    <parent
      link="Base_Link" />
    <child
      link="Hip2_Link" />
    <axis
      xyz="0 1 0" />
  </joint>
  <link
    name="Thigh2_Link">
    <inertial>
      <origin
        xyz="-0.050001 0.0043758 -0.039164"
        rpy="0 0 0" />
      <mass
        value="0.036775" />
      <inertia
        ixx="2.0073E-05"
        ixy="1.2849E-08"
        ixz="-5.7357E-06"
        iyy="1.7963E-05"
        iyz="4.5342E-10"
        izz="8.2574E-06" />
    </inertial>
    <visual>
      <origin
        xyz="0 0 0"
        rpy="0 0 0" />
      <geometry>
        <mesh
          filename="package://FullAssemV2_URDF_5/meshes/Thigh2_Link.STL" />
      </geometry>
      <material
        name="">
        <color
          rgba="0.75294 0.75294 0.75294 1" />
      </material>
    </visual>
    <collision>
      <origin
        xyz="0 0 0"
        rpy="0 0 0" />
      <geometry>
        <mesh
          filename="package://FullAssemV2_URDF_5/meshes/Thigh2_Link.STL" />
      </geometry>
    </collision>
  </link>
  <joint
    name="Thigh2_Joint"
    type="continuous">
    <origin
      xyz="0 -0.0039047 0"
      rpy="1.5708 0 0" />
    <parent
      link="Hip2_Link" />
    <child
      link="Thigh2_Link" />
    <axis
      xyz="0 0 1" />
  </joint>
  <link
    name="Shin2_Link">
    <inertial>
      <origin
        xyz="-0.027473 0.00052424 0.13428"
        rpy="0 0 0" />
      <mass
        value="0.057893" />
      <inertia
        ixx="5.1898E-06"
        ixy="-1.6896E-07"
        ixz="-2.1127E-06"
        iyy="9.8478E-05"
        iyz="-1.0889E-08"
        izz="9.4823E-05" />
    </inertial>
    <visual>
      <origin
        xyz="0 0 0"
        rpy="0 0 0" />
      <geometry>
        <mesh
          filename="package://FullAssemV2_URDF_5/meshes/Shin2_Link.STL" />
      </geometry>
      <material
        name="">
        <color
          rgba="0.75294 0.75294 0.75294 1" />
      </material>
    </visual>
    <collision>
      <origin
        xyz="0 0 0"
        rpy="0 0 0" />
      <geometry>
        <mesh
          filename="package://FullAssemV2_URDF_5/meshes/Shin2_Link.STL" />
      </geometry>
    </collision>
  </link>
  <joint
    name="Shin2_Joint"
    type="continuous">
    <origin
      xyz="0 0 0.034507"
      rpy="-3.1416 -1.0466 3.1416" />
    <parent
      link="Thigh2_Link" />
    <child
      link="Shin2_Link" />
    <axis
      xyz="0.86575 0 -0.50048" />
  </joint>
  <link
    name="Foot2_Link">
    <inertial>
      <origin
        xyz="0.0061601 0.14743 0.00015875"
        rpy="0 0 0" />
      <mass
        value="0.0091406" />
      <inertia
        ixx="1.4339E-06"
        ixy="6.6635E-08"
        ixz="9.0873E-14"
        iyy="7.4197E-07"
        iyz="-1.1846E-13"
        izz="1.335E-06" />
    </inertial>
    <visual>
      <origin
        xyz="0 0 0"
        rpy="0 0 0" />
      <geometry>
        <mesh
          filename="package://FullAssemV2_URDF_5/meshes/Foot2_Link.STL" />
      </geometry>
      <material
        name="">
        <color
          rgba="0.79216 0.81961 0.93333 1" />
      </material>
    </visual>
    <collision>
      <origin
        xyz="0 0 0"
        rpy="0 0 0" />
      <geometry>
        <mesh
          filename="package://FullAssemV2_URDF_5/meshes/Foot2_Link.STL" />
      </geometry>
    </collision>
  </link>
  <joint
    name="Foot2_Joint"
    type="continuous">
    <origin
      xyz="0 0 0"
      rpy="1.5708 -0.52416 3.1416" />
    <parent
      link="Shin2_Link" />
    <child
      link="Foot2_Link" />
    <axis
      xyz="1 0 0" />
  </joint>
  <link
    name="Hip3_Link">
    <inertial>
      <origin
        xyz="-0.017301 0.0041717 -0.0016669"
        rpy="0 0 0" />
      <mass
        value="0.026582" />
      <inertia
        ixx="4.4135E-06"
        ixy="6.9398E-09"
        ixz="6.2015E-08"
        iyy="4.1152E-06"
        iyz="-3.9832E-08"
        izz="7.2413E-06" />
    </inertial>
    <visual>
      <origin
        xyz="0 0 0"
        rpy="0 0 0" />
      <geometry>
        <mesh
          filename="package://FullAssemV2_URDF_5/meshes/Hip3_Link.STL" />
      </geometry>
      <material
        name="">
        <color
          rgba="0.79216 0.81961 0.93333 1" />
      </material>
    </visual>
    <collision>
      <origin
        xyz="0 0 0"
        rpy="0 0 0" />
      <geometry>
        <mesh
          filename="package://FullAssemV2_URDF_5/meshes/Hip3_Link.STL" />
      </geometry>
    </collision>
  </link>
  <joint
    name="Hip3_Joint"
    type="continuous">
    <origin
      xyz="0.039433 0.05348 0"
      rpy="1.5708 0 -2.7838" />
    <parent
      link="Base_Link" />
    <child
      link="Hip3_Link" />
    <axis
      xyz="0 1 0" />
  </joint>
  <link
    name="Thigh3_Link">
    <inertial>
      <origin
        xyz="-0.0612239609855549 0.00437576587462801 -0.0323494324720045"
        rpy="0 0 0" />
      <mass
        value="0.0367745529376103" />
      <inertia
        ixx="1.38981865500654E-05"
        ixy="1.30171143038279E-08"
        ixz="-8.34485590299359E-06"
        iyy="1.79630760279727E-05"
        iyz="3.41655457767964E-10"
        izz="1.44326475579248E-05" />
    </inertial>
    <visual>
      <origin
        xyz="0 0 0"
        rpy="0 0 0" />
      <geometry>
        <mesh
          filename="package://FullAssemV2_URDF_5/meshes/Thigh3_Link.STL" />
      </geometry>
      <material
        name="">
        <color
          rgba="0.752941176470588 0.752941176470588 0.752941176470588 1" />
      </material>
    </visual>
    <collision>
      <origin
        xyz="0 0 0"
        rpy="0 0 0" />
      <geometry>
        <mesh
          filename="package://FullAssemV2_URDF_5/meshes/Thigh3_Link.STL" />
      </geometry>
    </collision>
  </link>
  <joint
    name="Thigh3_Joint"
    type="continuous">
    <origin
      xyz="0 -0.0045321 0"
      rpy="1.5708 0 0" />
    <parent
      link="Hip3_Link" />
    <child
      link="Thigh3_Link" />
    <axis
      xyz="0 0 1" />
  </joint>
  <link
    name="Shin3_Link">
    <inertial>
      <origin
        xyz="-0.0175952045775863 0.000524247468325245 0.161106031339758"
        rpy="0 0 0" />
      <mass
        value="0.0578934409785742" />
      <inertia
        ixx="5.19137301410598E-06"
        ixy="-1.6878639007982E-07"
        ixz="-2.11391529173156E-06"
        iyy="9.84784530543327E-05"
        iyz="-1.08004114327676E-08"
        izz="9.48219041859225E-05" />
    </inertial>
    <visual>
      <origin
        xyz="0 0 0"
        rpy="0 0 0" />
      <geometry>
        <mesh
          filename="package://FullAssemV2_URDF_5/meshes/Shin3_Link.STL" />
      </geometry>
      <material
        name="">
        <color
          rgba="0.752941176470588 0.752941176470588 0.752941176470588 1" />
      </material>
    </visual>
    <collision>
      <origin
        xyz="0 0 0"
        rpy="0 0 0" />
      <geometry>
        <mesh
          filename="package://FullAssemV2_URDF_5/meshes/Shin3_Link.STL" />
      </geometry>
    </collision>
  </link>
  <joint
    name="Shin3_Joint"
    type="continuous">
    <origin
      xyz="0 0 0.057206"
      rpy="-3.1416 -1.0615 3.1416" />
    <parent
      link="Thigh3_Link" />
    <child
      link="Shin3_Link" />
    <axis
      xyz="0.87309 0 -0.48756" />
  </joint>
  <link
    name="Foot3_Link">
    <inertial>
      <origin
        xyz="0.00846241800333659 0.175922063446431 0.000158745167351128"
        rpy="0 0 0" />
      <mass
        value="0.00914057903727103" />
      <inertia
        ixx="1.43388054325383E-06"
        ixy="6.6635469140512E-08"
        ixz="4.07491870110971E-13"
        iyy="7.41969110605252E-07"
        iyz="-1.34870054809463E-13"
        izz="1.33502935775728E-06" />
    </inertial>
    <visual>
      <origin
        xyz="0 0 0"
        rpy="0 0 0" />
      <geometry>
        <mesh
          filename="package://FullAssemV2_URDF_5/meshes/Foot3_Link.STL" />
      </geometry>
      <material
        name="">
        <color
          rgba="0.792156862745098 0.819607843137255 0.933333333333333 1" />
      </material>
    </visual>
    <collision>
      <origin
        xyz="0 0 0"
        rpy="0 0 0" />
      <geometry>
        <mesh
          filename="package://FullAssemV2_URDF_5/meshes/Foot3_Link.STL" />
      </geometry>
    </collision>
  </link>
  <joint
    name="Foot3_Joint"
    type="continuous">
    <origin
      xyz="0 0 0"
      rpy="1.5708 -0.5093 3.1416" />
    <parent
      link="Shin3_Link" />
    <child
      link="Foot3_Link" />
    <axis
      xyz="1 0 0" />
  </joint>
  <link
    name="Hip4_Link">
    <inertial>
      <origin
        xyz="-0.017128 0.0041717 0.0013316"
        rpy="0 0 0" />
      <mass
        value="0.026582" />
      <inertia
        ixx="4.3875E-06"
        ixy="8.2775E-09"
        ixz="-1.6431E-07"
        iyy="4.1152E-06"
        iyz="-1.6691E-08"
        izz="7.2673E-06" />
    </inertial>
    <visual>
      <origin
        xyz="0 0 0"
        rpy="0 0 0" />
      <geometry>
        <mesh
          filename="package://FullAssemV2_URDF_5/meshes/Hip4_Link.STL" />
      </geometry>
      <material
        name="">
        <color
          rgba="0.79216 0.81961 0.93333 1" />
      </material>
    </visual>
    <collision>
      <origin
        xyz="0 0 0"
        rpy="0 0 0" />
      <geometry>
        <mesh
          filename="package://FullAssemV2_URDF_5/meshes/Hip4_Link.STL" />
      </geometry>
    </collision>
  </link>
  <joint
    name="Hip4_Joint"
    type="continuous">
    <origin
      xyz="-0.039433 0.05348 0"
      rpy="1.5708 0 -0.47257" />
    <parent
      link="Base_Link" />
    <child
      link="Hip4_Link" />
    <axis
      xyz="0 1 0" />
  </joint>
  <link
    name="Thigh4_Link">
    <inertial>
      <origin
        xyz="-0.0550280640784157 0.00437576544852812 -0.0370937545567517"
        rpy="0 0 0" />
      <mass
        value="0.0367745517137066" />
      <inertia
        ixx="1.77900985436127E-05"
        ixy="1.29240260785636E-08"
        ixz="-7.44100518201298E-06"
        iyy="1.79630759603318E-05"
        iyz="4.15572472440211E-10"
        izz="1.05407354595972E-05" />
    </inertial>
    <visual>
      <origin
        xyz="0 0 0"
        rpy="0 0 0" />
      <geometry>
        <mesh
          filename="package://FullAssemV2_URDF_5/meshes/Thigh4_Link.STL" />
      </geometry>
      <material
        name="">
        <color
          rgba="0.752941176470588 0.752941176470588 0.752941176470588 1" />
      </material>
    </visual>
    <collision>
      <origin
        xyz="0 0 0"
        rpy="0 0 0" />
      <geometry>
        <mesh
          filename="package://FullAssemV2_URDF_5/meshes/Thigh4_Link.STL" />
      </geometry>
    </collision>
  </link>
  <joint
    name="Thigh4_Joint"
    type="continuous">
    <origin
      xyz="0 -0.0043546 0"
      rpy="1.5708 0 0" />
    <parent
      link="Hip4_Link" />
    <child
      link="Thigh4_Link" />
    <axis
      xyz="0 0 1" />
  </joint>
  <link
    name="Shin4_Link">
    <inertial>
      <origin
        xyz="-0.0698470767345568 0.000524244290808738 0.125150499091729"
        rpy="0 0 0" />
      <mass
        value="0.0578934415312602" />
      <inertia
        ixx="5.18920741368609E-06"
        ixy="-1.69002633765832E-07"
        ixz="-2.11267767624196E-06"
        iyy="9.8478453092661E-05"
        iyz="-1.09259565687732E-08"
        izz="9.48240698434656E-05" />
    </inertial>
    <visual>
      <origin
        xyz="0 0 0"
        rpy="0 0 0" />
      <geometry>
        <mesh
          filename="package://FullAssemV2_URDF_5/meshes/Shin4_Link.STL" />
      </geometry>
      <material
        name="">
        <color
          rgba="0.752941176470588 0.752941176470588 0.752941176470588 1" />
      </material>
    </visual>
    <collision>
      <origin
        xyz="0 0 0"
        rpy="0 0 0" />
      <geometry>
        <mesh
          filename="package://FullAssemV2_URDF_5/meshes/Shin4_Link.STL" />
      </geometry>
    </collision>
  </link>
  <joint
    name="Shin4_Joint"
    type="continuous">
    <origin
      xyz="0 0 0.054559"
      rpy="-3.1416 -1.3327 3.1416" />
    <parent
      link="Thigh4_Link" />
    <child
      link="Shin4_Link" />
    <axis
      xyz="0.9718 0 -0.23582" />
  </joint>
  <link
    name="Foot4_Link">
    <inertial>
      <origin
        xyz="0.00367629248162111 0.127708621914678 0.000158739633252084"
        rpy="0 0 0" />
      <mass
        value="0.00914057907848054" />
      <inertia
        ixx="1.43388047627197E-06"
        ixy="6.66354983920578E-08"
        ixz="-7.44155415330433E-13"
        iyy="7.41969046146568E-07"
        iyz="-1.09981926807042E-13"
        izz="1.33502934802945E-06" />
    </inertial>
    <visual>
      <origin
        xyz="0 0 0"
        rpy="0 0 0" />
      <geometry>
        <mesh
          filename="package://FullAssemV2_URDF_5/meshes/Foot4_Link.STL" />
      </geometry>
      <material
        name="">
        <color
          rgba="0.792156862745098 0.819607843137255 0.933333333333333 1" />
      </material>
    </visual>
    <collision>
      <origin
        xyz="0 0 0"
        rpy="0 0 0" />
      <geometry>
        <mesh
          filename="package://FullAssemV2_URDF_5/meshes/Foot4_Link.STL" />
      </geometry>
    </collision>
  </link>
  <joint
    name="Foot4_Joint"
    type="continuous">
    <origin
      xyz="0 0 0"
      rpy="1.5708 -0.23806 3.1416" />
    <parent
      link="Shin4_Link" />
    <child
      link="Foot4_Link" />
    <axis
      xyz="1 0 0" />
  </joint>
</robot>